Workbook

Sheet Referrals
B2: ="Referrals Dashboard as of "&TEXT('Data Staging Provider Stats'!AQ5,"MMM")&" "&TEXT('Data Staging Provider Stats'!AQ5,"YYYY") -> Referrals Dashboard as of Oct 2025
B4: ='Data Staging Lag'!Q6 -> 366 | D4: ="Appointment Lag > 14 Days "&TEXT('Data Staging Provider Stats'!AQ5,"MMM")&" "&TEXT('Data Staging Provider Stats'!AQ5,"YYYY") -> Appointment Lag > 14 Days Oct 2025 | J4: Average Monthly Referrals (Last 12 Months) | P4: Top 5 YTD Practice Referrals
B6: ="Completed Referrals "&TEXT('Data Staging Provider Stats'!AQ5,"MMM")&" "&TEXT('Data Staging Provider Stats'!AQ5,"YYYY") -> Completed Referrals Oct 2025
B8: ='Data Staging Lag'!E6 -> 414
B10: ="Completed Referrals "&TEXT('Data Staging Lag'!E5,"MMM")&" "&TEXT('Data Staging Lag'!E5,"YYYY") -> Completed Referrals Oct 2024
B12: =CONCATENATE(ROUND(calcs!M3,2), "%",IF(calcs!M3<0," Decrease"," Increase")) -> -11.59% Decrease
O15: 1
B16: 523 | D16: Top 15 Referring Providers YTD | J16: Top 15 Referring Practices YTD | U16: Top 15 Referring Providers 13 Months of Data
D17: Provider | E17: New Patient | F17: Colonoscopy | G17: Total | J17: Practice | K17: New Patient | L17: Colonoscopy | M17: Total | U17: Provider | V17: =calcs!S3 -> 45931 | W17: =calcs!T3 -> 45901 | X17: =calcs!U3 -> 45870 | Y17: =calcs!V3 -> 45839 | Z17: =calcs!W3 -> 45809 | AA17: =calcs!X3 -> 45778 | AB17: =calcs!Y3 -> 45748 | AC17: =calcs!Z3 -> 45717 | ... AH17: =calcs!AE3 -> 45566 | AI17: Total
B18: ="Received Referrals " &TEXT('Data Staging Provider Stats'!AQ5,"MMM")&" "&TEXT('Data Staging Provider Stats'!AQ5,"YYYY") -> Received Referrals Oct 2025 | D18: =calcs!D8 -> All Other (5) | E18: =calcs!F8 -> 0 | F18: =calcs!G8 -> 0 | G18: =calcs!E8 -> 0 | J18: All Other | K18: =K34-SUM(K19:K33) -> 0 | L18: =L34-SUM(L19:L33) -> 0 | M18: =M34-SUM(M19:M33) -> 0 | U18: All Referrals | V18: ='Data Staging Lag'!Q6 -> 366 | W18: ='Data Staging Lag'!P6 -> 276 | X18: ='Data Staging Lag'!O6 -> 367 | Y18: ='Data Staging Lag'!N6 -> 332 | Z18: ='Data Staging Lag'!M6 -> 325 | AA18: ='Data Staging Lag'!L6 -> 384 | AB18: ='Data Staging Lag'!K6 -> 351 | AC18: ='Data Staging Lag'!J6 -> 366 | AD18: ='Data Staging Lag'!I6 -> 362 | AE18: ='Data Staging Lag'!H6 -> 331 | AF18: ='Data Staging Lag'!J6 -> 366 | AG18: ='Data Staging Lag'!F6 -> 353 | AH18: ='Data Staging Lag'!E6 -> 414 | AI18: =SUM(V18:AH18) -> 4593
B19: 534 | D19: =calcs!D9 -> Marcel Hilton | E19: =calcs!F9 -> 158 | F19: =calcs!G9 -> 159 | G19: =calcs!E9 -> 317 | J19: =calcs!D31 -> North Georiga Medical Clinic | K19: =calcs!F31 -> 158 | L19: =calcs!G31 -> 159 | M19: =calcs!E31 -> 317 | U19: =calcs!R4 -> Marcel Hilton | V19: =calcs!S4 -> 40 | W19: =calcs!T4 -> 27 | X19: =calcs!U4 -> 31 | Y19: =calcs!V4 -> 33 | Z19: =calcs!W4 -> 34 | AA19: =calcs!X4 -> 21 | AB19: =calcs!Y4 -> 34 | ... AI19: =calcs!AF4 -> 406
D20: =calcs!D10 -> Anna Stewart | E20: =calcs!F10 -> 86 | F20: =calcs!G10 -> 78 | G20: =calcs!E10 -> 164 | J20: =calcs!D32 -> Cornerstone Clinic | K20: =calcs!F32 -> 86 | L20: =calcs!G32 -> 78 | M20: =calcs!E32 -> 164 | U20: =calcs!R5 -> Anna Stewart | V20: =calcs!S5 -> 17 | W20: =calcs!T5 -> 13 | X20: =calcs!U5 -> 15 | Y20: =calcs!V5 -> 12 | Z20: =calcs!W5 -> 17 | AA20: =calcs!X5 -> 18 | AB20: =calcs!Y5 -> 17 | ... AI20: =calcs!AF5 -> 204
B21: ="Received Referrals "&TEXT('Data Staging Lag'!E5,"MMM")&" "&TEXT('Data Staging Lag'!E5,"YYYY") -> Received Referrals Oct 2024 | D21: =calcs!D11 -> Mohammad Frye | E21: =calcs!F11 -> 78 | F21: =calcs!G11 -> 80 | G21: =calcs!E11 -> 158 | J21: =calcs!D33 -> Neighborhood Medical Clinic | K21: =calcs!F33 -> 78 | L21: =calcs!G33 -> 80 | M21: =calcs!E33 -> 158 | U21: =calcs!R6 -> Mohammad Frye | V21: =calcs!S6 -> 26 | W21: =calcs!T6 -> 17 | X21: =calcs!U6 -> 14 | Y21: =calcs!V6 -> 11 | Z21: =calcs!W6 -> 12 | AA21: =calcs!X6 -> 19 | AB21: =calcs!Y6 -> 9 | ... AI21: =calcs!AF6 -> 205
B22: =CONCATENATE(ROUND(((B16-B19)/B19*100),2), "%",IF(((B16-B19)/B19)<0," Decrease"," Increase")) -> -2.06% Decrease | D22: =calcs!D12 -> Jerry Smith | E22: =calcs!F12 -> 77 | F22: =calcs!G12 -> 77 | G22: =calcs!E12 -> 154 | J22: =calcs!D34 -> Georgia Urgent Care Center | K22: =calcs!F34 -> 77 | L22: =calcs!G34 -> 77 | M22: =calcs!E34 -> 154 | U22: =calcs!R7 -> Jerry Smith | V22: =calcs!S7 -> 19 | W22: =calcs!T7 -> 12 | X22: =calcs!U7 -> 18 | Y22: =calcs!V7 -> 14 | Z22: =calcs!W7 -> 12 | AA22: =calcs!X7 -> 15 | AB22: =calcs!Y7 -> 20 | ... AI22: =calcs!AF7 -> 207
D23: =calcs!D13 -> Sabrina Byrd | E23: =calcs!F13 -> 64 | F23: =calcs!G13 -> 88 | G23: =calcs!E13 -> 152 | J23: =calcs!D35 -> Prime Care Medical Center | K23: =calcs!F35 -> 64 | L23: =calcs!G35 -> 88 | M23: =calcs!E35 -> 152 | U23: =calcs!R8 -> Sabrina Byrd | V23: =calcs!S8 -> 13 | W23: =calcs!T8 -> 13 | X23: =calcs!U8 -> 22 | Y23: =calcs!V8 -> 13 | Z23: =calcs!W8 -> 12 | AA23: =calcs!X8 -> 16 | AB23: =calcs!Y8 -> 21 | ... AI23: =calcs!AF8 -> 202
D24: =calcs!D14 -> Kelly Smith | E24: =calcs!F14 -> 79 | F24: =calcs!G14 -> 72 | G24: =calcs!E14 -> 151 | J24: =calcs!D36 -> Community Health Center | K24: =calcs!F36 -> 79 | L24: =calcs!G36 -> 72 | M24: =calcs!E36 -> 151 | U24: =calcs!R9 -> Kelly Smith | V24: =calcs!S9 -> 13 | W24: =calcs!T9 -> 16 | X24: =calcs!U9 -> 12 | Y24: =calcs!V9 -> 21 | Z24: =calcs!W9 -> 15 | AA24: =calcs!X9 -> 22 | AB24: =calcs!Y9 -> 14 | ... AI24: =calcs!AF9 -> 192
D25: =calcs!D15 -> Jessie Williams | E25: =calcs!F15 -> 76 | F25: =calcs!G15 -> 74 | G25: =calcs!E15 -> 150 | J25: =calcs!D37 -> Emergency Medical Clinic | K25: =calcs!F37 -> 76 | L25: =calcs!G37 -> 74 | M25: =calcs!E37 -> 150 | U25: =calcs!R10 -> Jessie Williams | V25: =calcs!S10 -> 18 | W25: =calcs!T10 -> 7 | X25: =calcs!U10 -> 13 | Y25: =calcs!V10 -> 12 | Z25: =calcs!W10 -> 16 | AA25: =calcs!X10 -> 18 | AB25: =calcs!Y10 -> 20 | ... AI25: =calcs!AF10 -> 196
D26: =calcs!D16 -> Larry Brown | E26: =calcs!F16 -> 68 | F26: =calcs!G16 -> 80 | G26: =calcs!E16 -> 148 | J26: =calcs!D38 -> East Georgia Medical Practice | K26: =calcs!F38 -> 68 | L26: =calcs!G38 -> 80 | M26: =calcs!E38 -> 148 | U26: =calcs!R11 -> Larry Brown | V26: =calcs!S11 -> 15 | W26: =calcs!T11 -> 14 | X26: =calcs!U11 -> 12 | Y26: =calcs!V11 -> 13 | Z26: =calcs!W11 -> 14 | AA26: =calcs!X11 -> 19 | AB26: =calcs!Y11 -> 15 | ... AI26: =calcs!AF11 -> 192
D27: =calcs!D17 -> Jenny Cameron | E27: =calcs!F17 -> 79 | F27: =calcs!G17 -> 66 | G27: =calcs!E17 -> 145 | J27: =calcs!D39 -> North Georgia Wellness Center | K27: =calcs!F39 -> 79 | L27: =calcs!G39 -> 66 | M27: =calcs!E39 -> 145 | U27: =calcs!R12 -> Jenny Cameron | V27: =calcs!S12 -> 11 | W27: =calcs!T12 -> 10 | X27: =calcs!U12 -> 14 | Y27: =calcs!V12 -> 15 | Z27: =calcs!W12 -> 23 | AA27: =calcs!X12 -> 12 | AB27: =calcs!Y12 -> 13 | ... AI27: =calcs!AF12 -> 183
B28: =SUM(G19:G28)/G34 -> 0.75033437 | D28: =calcs!D18 -> Fredrick Johnson | E28: =calcs!F18 -> 68 | F28: =calcs!G18 -> 76 | G28: =calcs!E18 -> 144 | J28: =calcs!D40 -> South Georgia Family Practice | K28: =calcs!F40 -> 68 | L28: =calcs!G40 -> 76 | M28: =calcs!E40 -> 144 | U28: =calcs!R13 -> Fredrick Johnson | V28: =calcs!S13 -> 10 | W28: =calcs!T13 -> 12 | X28: =calcs!U13 -> 17 | Y28: =calcs!V13 -> 20 | Z28: =calcs!W13 -> 9 | AA28: =calcs!X13 -> 17 | AB28: =calcs!Y13 -> 8 | ... AI28: =calcs!AF13 -> 193
D29: =calcs!D19 -> John Doe | E29: =calcs!F19 -> 73 | F29: =calcs!G19 -> 69 | G29: =calcs!E19 -> 142 | J29: =calcs!D41 -> Central Georigia Medical Practice | K29: =calcs!F41 -> 73 | L29: =calcs!G41 -> 69 | M29: =calcs!E41 -> 142 | U29: =calcs!R14 -> John Doe | V29: =calcs!S14 -> 13 | W29: =calcs!T14 -> 9 | X29: =calcs!U14 -> 11 | Y29: =calcs!V14 -> 15 | Z29: =calcs!W14 -> 14 | AA29: =calcs!X14 -> 15 | AB29: =calcs!Y14 -> 18 | ... AI29: =calcs!AF14 -> 177
D30: =calcs!D20 -> Donald Holmes | E30: =calcs!F20 -> 72 | F30: =calcs!G20 -> 65 | G30: =calcs!E20 -> 137 | J30: =calcs!D42 -> Georgia Medical Partners | K30: =calcs!F42 -> 72 | L30: =calcs!G42 -> 65 | M30: =calcs!E42 -> 137 | U30: =calcs!R15 -> Donald Holmes | V30: =calcs!S15 -> 17 | W30: =calcs!T15 -> 8 | X30: =calcs!U15 -> 11 | Y30: =calcs!V15 -> 21 | Z30: =calcs!W15 -> 16 | AA30: =calcs!X15 -> 16 | AB30: =calcs!Y15 -> 6 | ... AI30: =calcs!AF15 -> 189
B31: of Referrals From Top 10 Referring Providers | D31: =calcs!D21 -> Martha Thompson | E31: =calcs!F21 -> 72 | F31: =calcs!G21 -> 65 | G31: =calcs!E21 -> 137 | J31: =calcs!D43 -> Family Medical Practice | K31: =calcs!F43 -> 72 | L31: =calcs!G43 -> 65 | M31: =calcs!E43 -> 137 | U31: =calcs!R16 -> Martha Thompson | V31: =calcs!S16 -> 17 | W31: =calcs!T16 -> 8 | X31: =calcs!U16 -> 17 | Y31: =calcs!V16 -> 15 | Z31: =calcs!W16 -> 8 | AA31: =calcs!X16 -> 14 | AB31: =calcs!Y16 -> 14 | ... AI31: =calcs!AF16 -> 190
D32: =calcs!D22 -> Maria Jacobson | E32: =calcs!F22 -> 55 | F32: =calcs!G22 -> 74 | G32: =calcs!E22 -> 129 | J32: =calcs!D44 -> Georgia Medical Clinic | K32: =calcs!F44 -> 55 | L32: =calcs!G44 -> 74 | M32: =calcs!E44 -> 129 | U32: =calcs!R17 -> Maria Jacobson | V32: =calcs!S17 -> 15 | W32: =calcs!T17 -> 4 | X32: =calcs!U17 -> 14 | Y32: =calcs!V17 -> 10 | Z32: =calcs!W17 -> 13 | AA32: =calcs!X17 -> 16 | AB32: =calcs!Y17 -> 18 | ... AI32: =calcs!AF17 -> 181
D33: =calcs!D23 -> Frank Fredson | E33: =calcs!F23 -> 8 | F33: =calcs!G23 -> 7 | G33: =calcs!E23 -> 15 | J33: =calcs!D45 -> Georgia Healthcare Center | K33: =calcs!F45 -> 8 | L33: =calcs!G45 -> 7 | M33: =calcs!E45 -> 15 | U33: =calcs!R18 -> Frank Fredson | V33: =calcs!S18 -> 1 | W33: =calcs!T18 -> 3 | X33: =calcs!U18 -> 2 | Y33: =calcs!V18 -> 2 | Z33: =calcs!W18 -> 1 | AA33: =calcs!X18 -> 1 | AB33: =calcs!Y18 -> 2 | ... AI33: =calcs!AF18 -> 23
D34: Total | E34: =SUM(E18:E33) -> 1113 | F34: =SUM(F18:F33) -> 1130 | G34: =SUM(G18:G33) -> 2243 | I34: =SUM(F18:I28) -> 2533 | J34: Total | K34: =E34 -> 1113 | L34: =F34 -> 1130 | M34: =G34 -> 2243
D36: Monthly Referrals by Appointment Type | J36: Referral Counts Trending for Top 5 Referring Providers
B37: ='Data Staging Lag'!Q17 -> 16.784615
B39: Days
B41: Avg New Patient Appointment Lag (YTD)
B43: *Calculated From Created Date to Appointment Date*

Sheet calcs
D1: Appointment Lag > 14 Days | I1: Average Monthly Referrals
D2: New Patient | E2: ='Data Staging Lag'!Q22/'Data Staging Lag'!Q7 -> 0.37692308 | F2: =1-E2 -> 0.62307692 | I2: New Patient | J2: =AVERAGEIF('Data Staging Lag'!E7:P7,"<>0") -> 111 | L2: ='Data Staging Lag'!Q6 -> 366
D3: Colonoscopy | E3: ='Data Staging Lag'!Q23/'Data Staging Lag'!Q8 -> 0.4173913 | F3: =1-E3 -> 0.5826087 | I3: Colonoscopy | J3: =AVERAGEIF('Data Staging Lag'!E8:P8,"<>0") -> 113.58333 | L3: ='Data Staging Lag'!E6 -> 414 | M3: =((L2-L3)/L3)*100 -> -11.594203 | S3: ='Data Staging Provider Stats'!AQ5 -> 45931 | T3: ='Data Staging Provider Stats'!AN5 -> 45901 | U3: ='Data Staging Provider Stats'!AK5 -> 45870 | V3: ='Data Staging Provider Stats'!AH5 -> 45839 | W3: ='Data Staging Provider Stats'!AE5 -> 45809 | X3: ='Data Staging Provider Stats'!AB5 -> 45778 | Y3: ='Data Staging Provider Stats'!Y5 -> 45748 | Z3: ='Data Staging Provider Stats'!V5 -> 45717 | AA3: ='Data Staging Provider Stats'!S5 -> 45689 | AB3: ='Data Staging Provider Stats'!P5 -> 45658 | AC3: ='Data Staging Provider Stats'!M5 -> 45627 | AD3: ='Data Staging Provider Stats'!J5 -> 45597 | AE3: ='Data Staging Provider Stats'!G5 -> 45566 | AF3: Year Total
I4: Re-Establishing | J4: =AVERAGEIF('Data Staging Lag'!E9:P9,"<>0") -> 122.08333 | Q4: 1 | R4: =VLOOKUP(Q4,'Data Staging Provider Stats'!A:D,4,FALSE) -> Marcel Hilton | S4: =VLOOKUP($R4,'Data Staging Provider Stats'!$D:$AT,40,FALSE) -> 40 | T4: =VLOOKUP($R4,'Data Staging Provider Stats'!$D:$AT,37,FALSE) -> 27 | U4: =VLOOKUP($R4,'Data Staging Provider Stats'!$D:$AT,34,FALSE) -> 31 | V4: =VLOOKUP($R4,'Data Staging Provider Stats'!$D:$AT,31,FALSE) -> 33 | W4: =VLOOKUP($R4,'Data Staging Provider Stats'!$D:$AT,28,FALSE) -> 34 | X4: =VLOOKUP($R4,'Data Staging Provider Stats'!$D:$AT,25,FALSE) -> 21 | Y4: =VLOOKUP($R4,'Data Staging Provider Stats'!$D:$AT,22,FALSE) -> 34 | Z4: =VLOOKUP($R4,'Data Staging Provider Stats'!$D:$AT,19,FALSE) -> 31 | AA4: =VLOOKUP($R4,'Data Staging Provider Stats'!$D:$AT,16,FALSE) -> 34 | AB4: =VLOOKUP($R4,'Data Staging Provider Stats'!$D:$AT,13,FALSE) -> 32 | AC4: =VLOOKUP($R4,'Data Staging Provider Stats'!$D:$AT,10,FALSE) -> 23 | AD4: =VLOOKUP($R4,'Data Staging Provider Stats'!$D:$AT,7,FALSE) -> 33 | AE4: =VLOOKUP($R4,'Data Staging Provider Stats'!$D:$AT,4,FALSE) -> 33 | AF4: =SUM(S4:AE4) -> 406
D5: Top 15 Referring Providers | I5: Telehealth NP | J5: =AVERAGEIF('Data Staging Lag'!E10:P10,"<>0") -> #DIV/0! | Q5: 2 | R5: =VLOOKUP(Q5,'Data Staging Provider Stats'!A:D,4,FALSE) -> Anna Stewart | S5: =VLOOKUP($R5,'Data Staging Provider Stats'!$D:$AT,40,FALSE) -> 17 | T5: =VLOOKUP($R5,'Data Staging Provider Stats'!$D:$AT,37,FALSE) -> 13 | U5: =VLOOKUP($R5,'Data Staging Provider Stats'!$D:$AT,34,FALSE) -> 15 | V5: =VLOOKUP($R5,'Data Staging Provider Stats'!$D:$AT,31,FALSE) -> 12 | W5: =VLOOKUP($R5,'Data Staging Provider Stats'!$D:$AT,28,FALSE) -> 17 | X5: =VLOOKUP($R5,'Data Staging Provider Stats'!$D:$AT,25,FALSE) -> 18 | Y5: =VLOOKUP($R5,'Data Staging Provider Stats'!$D:$AT,22,FALSE) -> 17 | Z5: =VLOOKUP($R5,'Data Staging Provider Stats'!$D:$AT,19,FALSE) -> 18 | AA5: =VLOOKUP($R5,'Data Staging Provider Stats'!$D:$AT,16,FALSE) -> 20 | AB5: =VLOOKUP($R5,'Data Staging Provider Stats'!$D:$AT,13,FALSE) -> 17 | AC5: =VLOOKUP($R5,'Data Staging Provider Stats'!$D:$AT,10,FALSE) -> 12 | AD5: =VLOOKUP($R5,'Data Staging Provider Stats'!$D:$AT,7,FALSE) -> 14 | AE5: =VLOOKUP($R5,'Data Staging Provider Stats'!$D:$AT,4,FALSE) -> 14 | AF5: =SUM(S5:AE5) -> 204
Q6: 3 | R6: =VLOOKUP(Q6,'Data Staging Provider Stats'!A:D,4,FALSE) -> Mohammad Frye | S6: =VLOOKUP($R6,'Data Staging Provider Stats'!$D:$AT,40,FALSE) -> 26 | T6: =VLOOKUP($R6,'Data Staging Provider Stats'!$D:$AT,37,FALSE) -> 17 | U6: =VLOOKUP($R6,'Data Staging Provider Stats'!$D:$AT,34,FALSE) -> 14 | V6: =VLOOKUP($R6,'Data Staging Provider Stats'!$D:$AT,31,FALSE) -> 11 | W6: =VLOOKUP($R6,'Data Staging Provider Stats'!$D:$AT,28,FALSE) -> 12 | X6: =VLOOKUP($R6,'Data Staging Provider Stats'!$D:$AT,25,FALSE) -> 19 | Y6: =VLOOKUP($R6,'Data Staging Provider Stats'!$D:$AT,22,FALSE) -> 9 | Z6: =VLOOKUP($R6,'Data Staging Provider Stats'!$D:$AT,19,FALSE) -> 20 | AA6: =VLOOKUP($R6,'Data Staging Provider Stats'!$D:$AT,16,FALSE) -> 14 | AB6: =VLOOKUP($R6,'Data Staging Provider Stats'!$D:$AT,13,FALSE) -> 16 | AC6: =VLOOKUP($R6,'Data Staging Provider Stats'!$D:$AT,10,FALSE) -> 10 | AD6: =VLOOKUP($R6,'Data Staging Provider Stats'!$D:$AT,7,FALSE) -> 18 | AE6: =VLOOKUP($R6,'Data Staging Provider Stats'!$D:$AT,4,FALSE) -> 19 | AF6: =SUM(S6:AE6) -> 205
E7: Total | F7: New Patient | G7: Colonoscopy | Q7: 4 | R7: =VLOOKUP(Q7,'Data Staging Provider Stats'!A:D,4,FALSE) -> Jerry Smith | S7: =VLOOKUP($R7,'Data Staging Provider Stats'!$D:$AT,40,FALSE) -> 19 | T7: =VLOOKUP($R7,'Data Staging Provider Stats'!$D:$AT,37,FALSE) -> 12 | U7: =VLOOKUP($R7,'Data Staging Provider Stats'!$D:$AT,34,FALSE) -> 18 | V7: =VLOOKUP($R7,'Data Staging Provider Stats'!$D:$AT,31,FALSE) -> 14 | W7: =VLOOKUP($R7,'Data Staging Provider Stats'!$D:$AT,28,FALSE) -> 12 | X7: =VLOOKUP($R7,'Data Staging Provider Stats'!$D:$AT,25,FALSE) -> 15 | Y7: =VLOOKUP($R7,'Data Staging Provider Stats'!$D:$AT,22,FALSE) -> 20 | Z7: =VLOOKUP($R7,'Data Staging Provider Stats'!$D:$AT,19,FALSE) -> 17 | AA7: =VLOOKUP($R7,'Data Staging Provider Stats'!$D:$AT,16,FALSE) -> 10 | AB7: =VLOOKUP($R7,'Data Staging Provider Stats'!$D:$AT,13,FALSE) -> 17 | AC7: =VLOOKUP($R7,'Data Staging Provider Stats'!$D:$AT,10,FALSE) -> 12 | AD7: =VLOOKUP($R7,'Data Staging Provider Stats'!$D:$AT,7,FALSE) -> 18 | AE7: =VLOOKUP($R7,'Data Staging Provider Stats'!$D:$AT,4,FALSE) -> 23 | AF7: =SUM(S7:AE7) -> 207
C8: =COUNTIF('Data Staging Provider Stats'!D:D,"*")-11 -> 5 | D8: ="All Other (" &C8& ")" -> All Other (5) | E8: ='Data Staging Provider Stats'!AT7-SUM(calcs!E9:E23) -> 0 | F8: ='Data Staging Provider Stats'!AR7-SUM(calcs!F9:F23) -> 0 | G8: ='Data Staging Provider Stats'!AS7-SUM(calcs!G9:G23) -> 0 | Q8: 5 | R8: =VLOOKUP(Q8,'Data Staging Provider Stats'!A:D,4,FALSE) -> Sabrina Byrd | S8: =VLOOKUP($R8,'Data Staging Provider Stats'!$D:$AT,40,FALSE) -> 13 | T8: =VLOOKUP($R8,'Data Staging Provider Stats'!$D:$AT,37,FALSE) -> 13 | U8: =VLOOKUP($R8,'Data Staging Provider Stats'!$D:$AT,34,FALSE) -> 22 | V8: =VLOOKUP($R8,'Data Staging Provider Stats'!$D:$AT,31,FALSE) -> 13 | W8: =VLOOKUP($R8,'Data Staging Provider Stats'!$D:$AT,28,FALSE) -> 12 | X8: =VLOOKUP($R8,'Data Staging Provider Stats'!$D:$AT,25,FALSE) -> 16 | Y8: =VLOOKUP($R8,'Data Staging Provider Stats'!$D:$AT,22,FALSE) -> 21 | Z8: =VLOOKUP($R8,'Data Staging Provider Stats'!$D:$AT,19,FALSE) -> 17 | AA8: =VLOOKUP($R8,'Data Staging Provider Stats'!$D:$AT,16,FALSE) -> 15 | AB8: =VLOOKUP($R8,'Data Staging Provider Stats'!$D:$AT,13,FALSE) -> 10 | AC8: =VLOOKUP($R8,'Data Staging Provider Stats'!$D:$AT,10,FALSE) -> 12 | AD8: =VLOOKUP($R8,'Data Staging Provider Stats'!$D:$AT,7,FALSE) -> 19 | AE8: =VLOOKUP($R8,'Data Staging Provider Stats'!$D:$AT,4,FALSE) -> 19 | AF8: =SUM(S8:AE8) -> 202
C9: 1 | D9: =VLOOKUP(C9,'Data Staging Provider Stats'!A:D,4,FALSE) -> Marcel Hilton | E9: =VLOOKUP(D9,'Data Staging Provider Stats'!D:AT,43,FALSE) -> 317 | F9: =VLOOKUP($D9,'Data Staging Provider Stats'!$D:$AT,41,FALSE) -> 158 | G9: =VLOOKUP($D9,'Data Staging Provider Stats'!$D:$AT,42,FALSE) -> 159 | Q9: 6 | R9: =VLOOKUP(Q9,'Data Staging Provider Stats'!A:D,4,FALSE) -> Kelly Smith | S9: =VLOOKUP($R9,'Data Staging Provider Stats'!$D:$AT,40,FALSE) -> 13 | T9: =VLOOKUP($R9,'Data Staging Provider Stats'!$D:$AT,37,FALSE) -> 16 | U9: =VLOOKUP($R9,'Data Staging Provider Stats'!$D:$AT,34,FALSE) -> 12 | V9: =VLOOKUP($R9,'Data Staging Provider Stats'!$D:$AT,31,FALSE) -> 21 | W9: =VLOOKUP($R9,'Data Staging Provider Stats'!$D:$AT,28,FALSE) -> 15 | X9: =VLOOKUP($R9,'Data Staging Provider Stats'!$D:$AT,25,FALSE) -> 22 | Y9: =VLOOKUP($R9,'Data Staging Provider Stats'!$D:$AT,22,FALSE) -> 14 | Z9: =VLOOKUP($R9,'Data Staging Provider Stats'!$D:$AT,19,FALSE) -> 11 | AA9: =VLOOKUP($R9,'Data Staging Provider Stats'!$D:$AT,16,FALSE) -> 15 | AB9: =VLOOKUP($R9,'Data Staging Provider Stats'!$D:$AT,13,FALSE) -> 12 | AC9: =VLOOKUP($R9,'Data Staging Provider Stats'!$D:$AT,10,FALSE) -> 14 | AD9: =VLOOKUP($R9,'Data Staging Provider Stats'!$D:$AT,7,FALSE) -> 13 | AE9: =VLOOKUP($R9,'Data Staging Provider Stats'!$D:$AT,4,FALSE) -> 14 | AF9: =SUM(S9:AE9) -> 192
C10: 2 | D10: =VLOOKUP(C10,'Data Staging Provider Stats'!A:D,4,FALSE) -> Anna Stewart | E10: =VLOOKUP(D10,'Data Staging Provider Stats'!D:AT,43,FALSE) -> 164 | F10: =VLOOKUP($D10,'Data Staging Provider Stats'!$D:$AT,41,FALSE) -> 86 | G10: =VLOOKUP($D10,'Data Staging Provider Stats'!$D:$AT,42,FALSE) -> 78 | Q10: 7 | R10: =VLOOKUP(Q10,'Data Staging Provider Stats'!A:D,4,FALSE) -> Jessie Williams | S10: =VLOOKUP($R10,'Data Staging Provider Stats'!$D:$AT,40,FALSE) -> 18 | T10: =VLOOKUP($R10,'Data Staging Provider Stats'!$D:$AT,37,FALSE) -> 7 | U10: =VLOOKUP($R10,'Data Staging Provider Stats'!$D:$AT,34,FALSE) -> 13 | V10: =VLOOKUP($R10,'Data Staging Provider Stats'!$D:$AT,31,FALSE) -> 12 | W10: =VLOOKUP($R10,'Data Staging Provider Stats'!$D:$AT,28,FALSE) -> 16 | X10: =VLOOKUP($R10,'Data Staging Provider Stats'!$D:$AT,25,FALSE) -> 18 | Y10: =VLOOKUP($R10,'Data Staging Provider Stats'!$D:$AT,22,FALSE) -> 20 | Z10: =VLOOKUP($R10,'Data Staging Provider Stats'!$D:$AT,19,FALSE) -> 15 | AA10: =VLOOKUP($R10,'Data Staging Provider Stats'!$D:$AT,16,FALSE) -> 16 | AB10: =VLOOKUP($R10,'Data Staging Provider Stats'!$D:$AT,13,FALSE) -> 15 | AC10: =VLOOKUP($R10,'Data Staging Provider Stats'!$D:$AT,10,FALSE) -> 12 | AD10: =VLOOKUP($R10,'Data Staging Provider Stats'!$D:$AT,7,FALSE) -> 12 | AE10: =VLOOKUP($R10,'Data Staging Provider Stats'!$D:$AT,4,FALSE) -> 22 | AF10: =SUM(S10:AE10) -> 196
C11: 3 | D11: =VLOOKUP(C11,'Data Staging Provider Stats'!A:D,4,FALSE) -> Mohammad Frye | E11: =VLOOKUP(D11,'Data Staging Provider Stats'!D:AT,43,FALSE) -> 158 | F11: =VLOOKUP($D11,'Data Staging Provider Stats'!$D:$AT,41,FALSE) -> 78 | G11: =VLOOKUP($D11,'Data Staging Provider Stats'!$D:$AT,42,FALSE) -> 80 | Q11: 8 | R11: =VLOOKUP(Q11,'Data Staging Provider Stats'!A:D,4,FALSE) -> Larry Brown | S11: =VLOOKUP($R11,'Data Staging Provider Stats'!$D:$AT,40,FALSE) -> 15 | T11: =VLOOKUP($R11,'Data Staging Provider Stats'!$D:$AT,37,FALSE) -> 14 | U11: =VLOOKUP($R11,'Data Staging Provider Stats'!$D:$AT,34,FALSE) -> 12 | V11: =VLOOKUP($R11,'Data Staging Provider Stats'!$D:$AT,31,FALSE) -> 13 | W11: =VLOOKUP($R11,'Data Staging Provider Stats'!$D:$AT,28,FALSE) -> 14 | X11: =VLOOKUP($R11,'Data Staging Provider Stats'!$D:$AT,25,FALSE) -> 19 | Y11: =VLOOKUP($R11,'Data Staging Provider Stats'!$D:$AT,22,FALSE) -> 15 | Z11: =VLOOKUP($R11,'Data Staging Provider Stats'!$D:$AT,19,FALSE) -> 9 | AA11: =VLOOKUP($R11,'Data Staging Provider Stats'!$D:$AT,16,FALSE) -> 21 | AB11: =VLOOKUP($R11,'Data Staging Provider Stats'!$D:$AT,13,FALSE) -> 16 | AC11: =VLOOKUP($R11,'Data Staging Provider Stats'!$D:$AT,10,FALSE) -> 17 | AD11: =VLOOKUP($R11,'Data Staging Provider Stats'!$D:$AT,7,FALSE) -> 14 | AE11: =VLOOKUP($R11,'Data Staging Provider Stats'!$D:$AT,4,FALSE) -> 13 | AF11: =SUM(S11:AE11) -> 192
C12: 4 | D12: =VLOOKUP(C12,'Data Staging Provider Stats'!A:D,4,FALSE) -> Jerry Smith | E12: =VLOOKUP(D12,'Data Staging Provider Stats'!D:AT,43,FALSE) -> 154 | F12: =VLOOKUP($D12,'Data Staging Provider Stats'!$D:$AT,41,FALSE) -> 77 | G12: =VLOOKUP($D12,'Data Staging Provider Stats'!$D:$AT,42,FALSE) -> 77 | Q12: 9 | R12: =VLOOKUP(Q12,'Data Staging Provider Stats'!A:D,4,FALSE) -> Jenny Cameron | S12: =VLOOKUP($R12,'Data Staging Provider Stats'!$D:$AT,40,FALSE) -> 11 | T12: =VLOOKUP($R12,'Data Staging Provider Stats'!$D:$AT,37,FALSE) -> 10 | U12: =VLOOKUP($R12,'Data Staging Provider Stats'!$D:$AT,34,FALSE) -> 14 | V12: =VLOOKUP($R12,'Data Staging Provider Stats'!$D:$AT,31,FALSE) -> 15 | W12: =VLOOKUP($R12,'Data Staging Provider Stats'!$D:$AT,28,FALSE) -> 23 | X12: =VLOOKUP($R12,'Data Staging Provider Stats'!$D:$AT,25,FALSE) -> 12 | Y12: =VLOOKUP($R12,'Data Staging Provider Stats'!$D:$AT,22,FALSE) -> 13 | Z12: =VLOOKUP($R12,'Data Staging Provider Stats'!$D:$AT,19,FALSE) -> 14 | AA12: =VLOOKUP($R12,'Data Staging Provider Stats'!$D:$AT,16,FALSE) -> 15 | AB12: =VLOOKUP($R12,'Data Staging Provider Stats'!$D:$AT,13,FALSE) -> 18 | AC12: =VLOOKUP($R12,'Data Staging Provider Stats'!$D:$AT,10,FALSE) -> 16 | AD12: =VLOOKUP($R12,'Data Staging Provider Stats'!$D:$AT,7,FALSE) -> 9 | AE12: =VLOOKUP($R12,'Data Staging Provider Stats'!$D:$AT,4,FALSE) -> 13 | AF12: =SUM(S12:AE12) -> 183
C13: 5 | D13: =VLOOKUP(C13,'Data Staging Provider Stats'!A:D,4,FALSE) -> Sabrina Byrd | E13: =VLOOKUP(D13,'Data Staging Provider Stats'!D:AT,43,FALSE) -> 152 | F13: =VLOOKUP($D13,'Data Staging Provider Stats'!$D:$AT,41,FALSE) -> 64 | G13: =VLOOKUP($D13,'Data Staging Provider Stats'!$D:$AT,42,FALSE) -> 88 | Q13: 10 | R13: =VLOOKUP(Q13,'Data Staging Provider Stats'!A:D,4,FALSE) -> Fredrick Johnson | S13: =VLOOKUP($R13,'Data Staging Provider Stats'!$D:$AT,40,FALSE) -> 10 | T13: =VLOOKUP($R13,'Data Staging Provider Stats'!$D:$AT,37,FALSE) -> 12 | U13: =VLOOKUP($R13,'Data Staging Provider Stats'!$D:$AT,34,FALSE) -> 17 | V13: =VLOOKUP($R13,'Data Staging Provider Stats'!$D:$AT,31,FALSE) -> 20 | W13: =VLOOKUP($R13,'Data Staging Provider Stats'!$D:$AT,28,FALSE) -> 9 | X13: =VLOOKUP($R13,'Data Staging Provider Stats'!$D:$AT,25,FALSE) -> 17 | Y13: =VLOOKUP($R13,'Data Staging Provider Stats'!$D:$AT,22,FALSE) -> 8 | Z13: =VLOOKUP($R13,'Data Staging Provider Stats'!$D:$AT,19,FALSE) -> 28 | AA13: =VLOOKUP($R13,'Data Staging Provider Stats'!$D:$AT,16,FALSE) -> 7 | AB13: =VLOOKUP($R13,'Data Staging Provider Stats'!$D:$AT,13,FALSE) -> 16 | AC13: =VLOOKUP($R13,'Data Staging Provider Stats'!$D:$AT,10,FALSE) -> 12 | AD13: =VLOOKUP($R13,'Data Staging Provider Stats'!$D:$AT,7,FALSE) -> 20 | AE13: =VLOOKUP($R13,'Data Staging Provider Stats'!$D:$AT,4,FALSE) -> 17 | AF13: =SUM(S13:AE13) -> 193
C14: 6 | D14: =VLOOKUP(C14,'Data Staging Provider Stats'!A:D,4,FALSE) -> Kelly Smith | E14: =VLOOKUP(D14,'Data Staging Provider Stats'!D:AT,43,FALSE) -> 151 | F14: =VLOOKUP($D14,'Data Staging Provider Stats'!$D:$AT,41,FALSE) -> 79 | G14: =VLOOKUP($D14,'Data Staging Provider Stats'!$D:$AT,42,FALSE) -> 72 | Q14: 11 | R14: =VLOOKUP(Q14,'Data Staging Provider Stats'!A:D,4,FALSE) -> John Doe | S14: =VLOOKUP($R14,'Data Staging Provider Stats'!$D:$AT,40,FALSE) -> 13 | T14: =VLOOKUP($R14,'Data Staging Provider Stats'!$D:$AT,37,FALSE) -> 9 | U14: =VLOOKUP($R14,'Data Staging Provider Stats'!$D:$AT,34,FALSE) -> 11 | V14: =VLOOKUP($R14,'Data Staging Provider Stats'!$D:$AT,31,FALSE) -> 15 | W14: =VLOOKUP($R14,'Data Staging Provider Stats'!$D:$AT,28,FALSE) -> 14 | X14: =VLOOKUP($R14,'Data Staging Provider Stats'!$D:$AT,25,FALSE) -> 15 | Y14: =VLOOKUP($R14,'Data Staging Provider Stats'!$D:$AT,22,FALSE) -> 18 | Z14: =VLOOKUP($R14,'Data Staging Provider Stats'!$D:$AT,19,FALSE) -> 19 | AA14: =VLOOKUP($R14,'Data Staging Provider Stats'!$D:$AT,16,FALSE) -> 14 | AB14: =VLOOKUP($R14,'Data Staging Provider Stats'!$D:$AT,13,FALSE) -> 14 | AC14: =VLOOKUP($R14,'Data Staging Provider Stats'!$D:$AT,10,FALSE) -> 12 | AD14: =VLOOKUP($R14,'Data Staging Provider Stats'!$D:$AT,7,FALSE) -> 6 | AE14: =VLOOKUP($R14,'Data Staging Provider Stats'!$D:$AT,4,FALSE) -> 17 | AF14: =SUM(S14:AE14) -> 177
C15: 7 | D15: =VLOOKUP(C15,'Data Staging Provider Stats'!A:D,4,FALSE) -> Jessie Williams | E15: =VLOOKUP(D15,'Data Staging Provider Stats'!D:AT,43,FALSE) -> 150 | F15: =VLOOKUP($D15,'Data Staging Provider Stats'!$D:$AT,41,FALSE) -> 76 | G15: =VLOOKUP($D15,'Data Staging Provider Stats'!$D:$AT,42,FALSE) -> 74 | Q15: 12 | R15: =VLOOKUP(Q15,'Data Staging Provider Stats'!A:D,4,FALSE) -> Donald Holmes | S15: =VLOOKUP($R15,'Data Staging Provider Stats'!$D:$AT,40,FALSE) -> 17 | T15: =VLOOKUP($R15,'Data Staging Provider Stats'!$D:$AT,37,FALSE) -> 8 | U15: =VLOOKUP($R15,'Data Staging Provider Stats'!$D:$AT,34,FALSE) -> 11 | V15: =VLOOKUP($R15,'Data Staging Provider Stats'!$D:$AT,31,FALSE) -> 21 | W15: =VLOOKUP($R15,'Data Staging Provider Stats'!$D:$AT,28,FALSE) -> 16 | X15: =VLOOKUP($R15,'Data Staging Provider Stats'!$D:$AT,25,FALSE) -> 16 | Y15: =VLOOKUP($R15,'Data Staging Provider Stats'!$D:$AT,22,FALSE) -> 6 | Z15: =VLOOKUP($R15,'Data Staging Provider Stats'!$D:$AT,19,FALSE) -> 13 | AA15: =VLOOKUP($R15,'Data Staging Provider Stats'!$D:$AT,16,FALSE) -> 12 | AB15: =VLOOKUP($R15,'Data Staging Provider Stats'!$D:$AT,13,FALSE) -> 17 | AC15: =VLOOKUP($R15,'Data Staging Provider Stats'!$D:$AT,10,FALSE) -> 17 | AD15: =VLOOKUP($R15,'Data Staging Provider Stats'!$D:$AT,7,FALSE) -> 19 | AE15: =VLOOKUP($R15,'Data Staging Provider Stats'!$D:$AT,4,FALSE) -> 16 | AF15: =SUM(S15:AE15) -> 189
C16: 8 | D16: =VLOOKUP(C16,'Data Staging Provider Stats'!A:D,4,FALSE) -> Larry Brown | E16: =VLOOKUP(D16,'Data Staging Provider Stats'!D:AT,43,FALSE) -> 148 | F16: =VLOOKUP($D16,'Data Staging Provider Stats'!$D:$AT,41,FALSE) -> 68 | G16: =VLOOKUP($D16,'Data Staging Provider Stats'!$D:$AT,42,FALSE) -> 80 | Q16: 13 | R16: =VLOOKUP(Q16,'Data Staging Provider Stats'!A:D,4,FALSE) -> Martha Thompson | S16: =VLOOKUP($R16,'Data Staging Provider Stats'!$D:$AT,40,FALSE) -> 17 | T16: =VLOOKUP($R16,'Data Staging Provider Stats'!$D:$AT,37,FALSE) -> 8 | U16: =VLOOKUP($R16,'Data Staging Provider Stats'!$D:$AT,34,FALSE) -> 17 | V16: =VLOOKUP($R16,'Data Staging Provider Stats'!$D:$AT,31,FALSE) -> 15 | W16: =VLOOKUP($R16,'Data Staging Provider Stats'!$D:$AT,28,FALSE) -> 8 | X16: =VLOOKUP($R16,'Data Staging Provider Stats'!$D:$AT,25,FALSE) -> 14 | Y16: =VLOOKUP($R16,'Data Staging Provider Stats'!$D:$AT,22,FALSE) -> 14 | Z16: =VLOOKUP($R16,'Data Staging Provider Stats'!$D:$AT,19,FALSE) -> 12 | AA16: =VLOOKUP($R16,'Data Staging Provider Stats'!$D:$AT,16,FALSE) -> 14 | AB16: =VLOOKUP($R16,'Data Staging Provider Stats'!$D:$AT,13,FALSE) -> 18 | AC16: =VLOOKUP($R16,'Data Staging Provider Stats'!$D:$AT,10,FALSE) -> 14 | AD16: =VLOOKUP($R16,'Data Staging Provider Stats'!$D:$AT,7,FALSE) -> 20 | AE16: =VLOOKUP($R16,'Data Staging Provider Stats'!$D:$AT,4,FALSE) -> 19 | AF16: =SUM(S16:AE16) -> 190
C17: 9 | D17: =VLOOKUP(C17,'Data Staging Provider Stats'!A:D,4,FALSE) -> Jenny Cameron | E17: =VLOOKUP(D17,'Data Staging Provider Stats'!D:AT,43,FALSE) -> 145 | F17: =VLOOKUP($D17,'Data Staging Provider Stats'!$D:$AT,41,FALSE) -> 79 | G17: =VLOOKUP($D17,'Data Staging Provider Stats'!$D:$AT,42,FALSE) -> 66 | Q17: 14 | R17: =VLOOKUP(Q17,'Data Staging Provider Stats'!A:D,4,FALSE) -> Maria Jacobson | S17: =VLOOKUP($R17,'Data Staging Provider Stats'!$D:$AT,40,FALSE) -> 15 | T17: =VLOOKUP($R17,'Data Staging Provider Stats'!$D:$AT,37,FALSE) -> 4 | U17: =VLOOKUP($R17,'Data Staging Provider Stats'!$D:$AT,34,FALSE) -> 14 | V17: =VLOOKUP($R17,'Data Staging Provider Stats'!$D:$AT,31,FALSE) -> 10 | W17: =VLOOKUP($R17,'Data Staging Provider Stats'!$D:$AT,28,FALSE) -> 13 | X17: =VLOOKUP($R17,'Data Staging Provider Stats'!$D:$AT,25,FALSE) -> 16 | Y17: =VLOOKUP($R17,'Data Staging Provider Stats'!$D:$AT,22,FALSE) -> 18 | Z17: =VLOOKUP($R17,'Data Staging Provider Stats'!$D:$AT,19,FALSE) -> 10 | AA17: =VLOOKUP($R17,'Data Staging Provider Stats'!$D:$AT,16,FALSE) -> 20 | AB17: =VLOOKUP($R17,'Data Staging Provider Stats'!$D:$AT,13,FALSE) -> 9 | AC17: =VLOOKUP($R17,'Data Staging Provider Stats'!$D:$AT,10,FALSE) -> 21 | AD17: =VLOOKUP($R17,'Data Staging Provider Stats'!$D:$AT,7,FALSE) -> 19 | AE17: =VLOOKUP($R17,'Data Staging Provider Stats'!$D:$AT,4,FALSE) -> 12 | AF17: =SUM(S17:AE17) -> 181
C18: 10 | D18: =VLOOKUP(C18,'Data Staging Provider Stats'!A:D,4,FALSE) -> Fredrick Johnson | E18: =VLOOKUP(D18,'Data Staging Provider Stats'!D:AT,43,FALSE) -> 144 | F18: =VLOOKUP($D18,'Data Staging Provider Stats'!$D:$AT,41,FALSE) -> 68 | G18: =VLOOKUP($D18,'Data Staging Provider Stats'!$D:$AT,42,FALSE) -> 76 | Q18: 15 | R18: =VLOOKUP(Q18,'Data Staging Provider Stats'!A:D,4,FALSE) -> Frank Fredson | S18: =VLOOKUP($R18,'Data Staging Provider Stats'!$D:$AT,40,FALSE) -> 1 | T18: =VLOOKUP($R18,'Data Staging Provider Stats'!$D:$AT,37,FALSE) -> 3 | U18: =VLOOKUP($R18,'Data Staging Provider Stats'!$D:$AT,34,FALSE) -> 2 | V18: =VLOOKUP($R18,'Data Staging Provider Stats'!$D:$AT,31,FALSE) -> 2 | W18: =VLOOKUP($R18,'Data Staging Provider Stats'!$D:$AT,28,FALSE) -> 1 | X18: =VLOOKUP($R18,'Data Staging Provider Stats'!$D:$AT,25,FALSE) -> 1 | Y18: =VLOOKUP($R18,'Data Staging Provider Stats'!$D:$AT,22,FALSE) -> 2 | Z18: =VLOOKUP($R18,'Data Staging Provider Stats'!$D:$AT,19,FALSE) -> 2 | AA18: =VLOOKUP($R18,'Data Staging Provider Stats'!$D:$AT,16,FALSE) -> 0 | AB18: =VLOOKUP($R18,'Data Staging Provider Stats'!$D:$AT,13,FALSE) -> 1 | AC18: =VLOOKUP($R18,'Data Staging Provider Stats'!$D:$AT,10,FALSE) -> 0 | AD18: =VLOOKUP($R18,'Data Staging Provider Stats'!$D:$AT,7,FALSE) -> 1 | AE18: =VLOOKUP($R18,'Data Staging Provider Stats'!$D:$AT,4,FALSE) -> 7 | AF18: =SUM(S18:AE18) -> 23
C19: 11 | D19: =VLOOKUP(C19,'Data Staging Provider Stats'!A:D,4,FALSE) -> John Doe | E19: =VLOOKUP(D19,'Data Staging Provider Stats'!D:AT,43,FALSE) -> 142 | F19: =VLOOKUP($D19,'Data Staging Provider Stats'!$D:$AT,41,FALSE) -> 73 | G19: =VLOOKUP($D19,'Data Staging Provider Stats'!$D:$AT,42,FALSE) -> 69 | R19: Total | S19: =VLOOKUP($R19,'Data Staging Provider Stats'!$D:$AT,40,FALSE) -> 245 | T19: =VLOOKUP($R19,'Data Staging Provider Stats'!$D:$AT,37,FALSE) -> 173 | U19: =VLOOKUP($R19,'Data Staging Provider Stats'!$D:$AT,34,FALSE) -> 223 | V19: =VLOOKUP($R19,'Data Staging Provider Stats'!$D:$AT,31,FALSE) -> 227 | W19: =VLOOKUP($R19,'Data Staging Provider Stats'!$D:$AT,28,FALSE) -> 216 | X19: =VLOOKUP($R19,'Data Staging Provider Stats'!$D:$AT,25,FALSE) -> 239 | Y19: =VLOOKUP($R19,'Data Staging Provider Stats'!$D:$AT,22,FALSE) -> 229 | Z19: =VLOOKUP($R19,'Data Staging Provider Stats'!$D:$AT,19,FALSE) -> 236 | AA19: =VLOOKUP($R19,'Data Staging Provider Stats'!$D:$AT,16,FALSE) -> 227 | AB19: =VLOOKUP($R19,'Data Staging Provider Stats'!$D:$AT,13,FALSE) -> 228 | AC19: =VLOOKUP($R19,'Data Staging Provider Stats'!$D:$AT,10,FALSE) -> 204 | AD19: =VLOOKUP($R19,'Data Staging Provider Stats'!$D:$AT,7,FALSE) -> 235 | AE19: =VLOOKUP($R19,'Data Staging Provider Stats'!$D:$AT,4,FALSE) -> 258 | AF19: =SUM(S19:AE19) -> 2940
C20: 12 | D20: =VLOOKUP(C20,'Data Staging Provider Stats'!A:D,4,FALSE) -> Donald Holmes | E20: =VLOOKUP(D20,'Data Staging Provider Stats'!D:AT,43,FALSE) -> 137 | F20: =VLOOKUP($D20,'Data Staging Provider Stats'!$D:$AT,41,FALSE) -> 72 | G20: =VLOOKUP($D20,'Data Staging Provider Stats'!$D:$AT,42,FALSE) -> 65 | I20: Referral Counts Trending for Top 5 Referring Providers
C21: 13 | D21: =VLOOKUP(C21,'Data Staging Provider Stats'!A:D,4,FALSE) -> Martha Thompson | E21: =VLOOKUP(D21,'Data Staging Provider Stats'!D:AT,43,FALSE) -> 137 | F21: =VLOOKUP($D21,'Data Staging Provider Stats'!$D:$AT,41,FALSE) -> 72 | G21: =VLOOKUP($D21,'Data Staging Provider Stats'!$D:$AT,42,FALSE) -> 65 | J21: ='Data Staging Lag'!L5 -> 45778 | K21: ='Data Staging Lag'!M5 -> 45809 | L21: ='Data Staging Lag'!N5 -> 45839 | M21: ='Data Staging Lag'!O5 -> 45870 | N21: ='Data Staging Lag'!P5 -> 45901 | O21: ='Data Staging Lag'!Q5 -> 45931
C22: 14 | D22: =VLOOKUP(C22,'Data Staging Provider Stats'!A:D,4,FALSE) -> Maria Jacobson | E22: =VLOOKUP(D22,'Data Staging Provider Stats'!D:AT,43,FALSE) -> 129 | F22: =VLOOKUP($D22,'Data Staging Provider Stats'!$D:$AT,41,FALSE) -> 55 | G22: =VLOOKUP($D22,'Data Staging Provider Stats'!$D:$AT,42,FALSE) -> 74 | I22: =D9 -> Marcel Hilton | J22: =SUMIFS('Data Staging Provider Stats'!$AB:$AB,'Data Staging Provider Stats'!$D:$D,calcs!$I22) -> 21 | K22: =SUMIFS('Data Staging Provider Stats'!$AE:$AE,'Data Staging Provider Stats'!$D:$D,calcs!$I22) -> 34 | L22: =SUMIFS('Data Staging Provider Stats'!$AH:$AH,'Data Staging Provider Stats'!$D:$D,calcs!$I22) -> 33 | M22: =SUMIFS('Data Staging Provider Stats'!$AK:$AK,'Data Staging Provider Stats'!$D:$D,calcs!$I22) -> 31 | N22: =SUMIFS('Data Staging Provider Stats'!$AN:$AN,'Data Staging Provider Stats'!$D:$D,calcs!$I22) -> 27 | O22: =SUMIFS('Data Staging Provider Stats'!$AQ:$AQ,'Data Staging Provider Stats'!$D:$D,calcs!$I22) -> 40 | S22: Oct - 2024 | T22: Nov - 2024 | U22: Dec - 2024 | V22: Jan - 2025 | W22: Feb - 2025 | X22: Mar - 2025 | Y22: Apr - 2025 | Z22: May - 2025 | AA22: Jun - 2025 | AB22: Jul - 2025 | AC22: Aug - 2025 | AD22: Sep - 2025 | AE22: Oct - 2025
C23: 15 | D23: =VLOOKUP(C23,'Data Staging Provider Stats'!A:D,4,FALSE) -> Frank Fredson | E23: =VLOOKUP(D23,'Data Staging Provider Stats'!D:AT,43,FALSE) -> 15 | F23: =VLOOKUP($D23,'Data Staging Provider Stats'!$D:$AT,41,FALSE) -> 8 | G23: =VLOOKUP($D23,'Data Staging Provider Stats'!$D:$AT,42,FALSE) -> 7 | I23: =D10 -> Anna Stewart | J23: =SUMIFS('Data Staging Provider Stats'!$AB:$AB,'Data Staging Provider Stats'!$D:$D,calcs!$I23) -> 18 | K23: =SUMIFS('Data Staging Provider Stats'!$AE:$AE,'Data Staging Provider Stats'!$D:$D,calcs!$I23) -> 17 | L23: =SUMIFS('Data Staging Provider Stats'!$AH:$AH,'Data Staging Provider Stats'!$D:$D,calcs!$I23) -> 12 | M23: =SUMIFS('Data Staging Provider Stats'!$AK:$AK,'Data Staging Provider Stats'!$D:$D,calcs!$I23) -> 15 | N23: =SUMIFS('Data Staging Provider Stats'!$AN:$AN,'Data Staging Provider Stats'!$D:$D,calcs!$I23) -> 13 | O23: =SUMIFS('Data Staging Provider Stats'!$AQ:$AQ,'Data Staging Provider Stats'!$D:$D,calcs!$I23) -> 17 | S23: ='Data Staging Lag'!E6 -> 414 | T23: ='Data Staging Lag'!F6 -> 353 | U23: ='Data Staging Lag'!G6 -> 299 | V23: ='Data Staging Lag'!H6 -> 331 | W23: ='Data Staging Lag'!I6 -> 362 | X23: ='Data Staging Lag'!J6 -> 366 | Y23: ='Data Staging Lag'!K6 -> 351 | Z23: ='Data Staging Lag'!L6 -> 384 | ... AE23: ='Data Staging Lag'!Q6 -> 366
I24: =D11 -> Mohammad Frye | J24: =SUMIFS('Data Staging Provider Stats'!$AB:$AB,'Data Staging Provider Stats'!$D:$D,calcs!$I24) -> 19 | K24: =SUMIFS('Data Staging Provider Stats'!$AE:$AE,'Data Staging Provider Stats'!$D:$D,calcs!$I24) -> 12 | L24: =SUMIFS('Data Staging Provider Stats'!$AH:$AH,'Data Staging Provider Stats'!$D:$D,calcs!$I24) -> 11 | M24: =SUMIFS('Data Staging Provider Stats'!$AK:$AK,'Data Staging Provider Stats'!$D:$D,calcs!$I24) -> 14 | N24: =SUMIFS('Data Staging Provider Stats'!$AN:$AN,'Data Staging Provider Stats'!$D:$D,calcs!$I24) -> 17 | O24: =SUMIFS('Data Staging Provider Stats'!$AQ:$AQ,'Data Staging Provider Stats'!$D:$D,calcs!$I24) -> 26
I25: =D12 -> Jerry Smith | J25: =SUMIFS('Data Staging Provider Stats'!$AB:$AB,'Data Staging Provider Stats'!$D:$D,calcs!$I25) -> 15 | K25: =SUMIFS('Data Staging Provider Stats'!$AE:$AE,'Data Staging Provider Stats'!$D:$D,calcs!$I25) -> 12 | L25: =SUMIFS('Data Staging Provider Stats'!$AH:$AH,'Data Staging Provider Stats'!$D:$D,calcs!$I25) -> 14 | M25: =SUMIFS('Data Staging Provider Stats'!$AK:$AK,'Data Staging Provider Stats'!$D:$D,calcs!$I25) -> 18 | N25: =SUMIFS('Data Staging Provider Stats'!$AN:$AN,'Data Staging Provider Stats'!$D:$D,calcs!$I25) -> 12 | O25: =SUMIFS('Data Staging Provider Stats'!$AQ:$AQ,'Data Staging Provider Stats'!$D:$D,calcs!$I25) -> 19
I26: =D13 -> Sabrina Byrd | J26: =SUMIFS('Data Staging Provider Stats'!$AB:$AB,'Data Staging Provider Stats'!$D:$D,calcs!$I26) -> 16 | K26: =SUMIFS('Data Staging Provider Stats'!$AE:$AE,'Data Staging Provider Stats'!$D:$D,calcs!$I26) -> 12 | L26: =SUMIFS('Data Staging Provider Stats'!$AH:$AH,'Data Staging Provider Stats'!$D:$D,calcs!$I26) -> 13 | M26: =SUMIFS('Data Staging Provider Stats'!$AK:$AK,'Data Staging Provider Stats'!$D:$D,calcs!$I26) -> 22 | N26: =SUMIFS('Data Staging Provider Stats'!$AN:$AN,'Data Staging Provider Stats'!$D:$D,calcs!$I26) -> 13 | O26: =SUMIFS('Data Staging Provider Stats'!$AQ:$AQ,'Data Staging Provider Stats'!$D:$D,calcs!$I26) -> 13
D27: Top 15 Referring Practices
E29: Total | F29: New Patient | G29: Colonoscopy
D30: All Other
C31: 1 | D31: =VLOOKUP(C31,'Data Staging Practice Stats'!B:D,3,FALSE) -> North Georiga Medical Clinic | E31: =VLOOKUP(D31,'Data Staging Practice Stats'!D:AT,43,FALSE) -> 317 | F31: =VLOOKUP(D31,'Data Staging Practice Stats'!D:AT,41,FALSE) -> 158 | G31: =VLOOKUP(D31,'Data Staging Practice Stats'!D:AT,42,FALSE) -> 159
C32: 2 | D32: =VLOOKUP(C32,'Data Staging Practice Stats'!B:D,3,FALSE) -> Cornerstone Clinic | E32: =VLOOKUP(D32,'Data Staging Practice Stats'!D:AT,43,FALSE) -> 164 | F32: =VLOOKUP(D32,'Data Staging Practice Stats'!D:AT,41,FALSE) -> 86 | G32: =VLOOKUP(D32,'Data Staging Practice Stats'!D:AT,42,FALSE) -> 78
C33: 3 | D33: =VLOOKUP(C33,'Data Staging Practice Stats'!B:D,3,FALSE) -> Neighborhood Medical Clinic | E33: =VLOOKUP(D33,'Data Staging Practice Stats'!D:AT,43,FALSE) -> 158 | F33: =VLOOKUP(D33,'Data Staging Practice Stats'!D:AT,41,FALSE) -> 78 | G33: =VLOOKUP(D33,'Data Staging Practice Stats'!D:AT,42,FALSE) -> 80
C34: 4 | D34: =VLOOKUP(C34,'Data Staging Practice Stats'!B:D,3,FALSE) -> Georgia Urgent Care Center | E34: =VLOOKUP(D34,'Data Staging Practice Stats'!D:AT,43,FALSE) -> 154 | F34: =VLOOKUP(D34,'Data Staging Practice Stats'!D:AT,41,FALSE) -> 77 | G34: =VLOOKUP(D34,'Data Staging Practice Stats'!D:AT,42,FALSE) -> 77
C35: 5 | D35: =VLOOKUP(C35,'Data Staging Practice Stats'!B:D,3,FALSE) -> Prime Care Medical Center | E35: =VLOOKUP(D35,'Data Staging Practice Stats'!D:AT,43,FALSE) -> 152 | F35: =VLOOKUP(D35,'Data Staging Practice Stats'!D:AT,41,FALSE) -> 64 | G35: =VLOOKUP(D35,'Data Staging Practice Stats'!D:AT,42,FALSE) -> 88
C36: 6 | D36: =VLOOKUP(C36,'Data Staging Practice Stats'!B:D,3,FALSE) -> Community Health Center | E36: =VLOOKUP(D36,'Data Staging Practice Stats'!D:AT,43,FALSE) -> 151 | F36: =VLOOKUP(D36,'Data Staging Practice Stats'!D:AT,41,FALSE) -> 79 | G36: =VLOOKUP(D36,'Data Staging Practice Stats'!D:AT,42,FALSE) -> 72
C37: 7 | D37: =VLOOKUP(C37,'Data Staging Practice Stats'!B:D,3,FALSE) -> Emergency Medical Clinic | E37: =VLOOKUP(D37,'Data Staging Practice Stats'!D:AT,43,FALSE) -> 150 | F37: =VLOOKUP(D37,'Data Staging Practice Stats'!D:AT,41,FALSE) -> 76 | G37: =VLOOKUP(D37,'Data Staging Practice Stats'!D:AT,42,FALSE) -> 74
C38: 8 | D38: =VLOOKUP(C38,'Data Staging Practice Stats'!B:D,3,FALSE) -> East Georgia Medical Practice | E38: =VLOOKUP(D38,'Data Staging Practice Stats'!D:AT,43,FALSE) -> 148 | F38: =VLOOKUP(D38,'Data Staging Practice Stats'!D:AT,41,FALSE) -> 68 | G38: =VLOOKUP(D38,'Data Staging Practice Stats'!D:AT,42,FALSE) -> 80
C39: 9 | D39: =VLOOKUP(C39,'Data Staging Practice Stats'!B:D,3,FALSE) -> North Georgia Wellness Center | E39: =VLOOKUP(D39,'Data Staging Practice Stats'!D:AT,43,FALSE) -> 145 | F39: =VLOOKUP(D39,'Data Staging Practice Stats'!D:AT,41,FALSE) -> 79 | G39: =VLOOKUP(D39,'Data Staging Practice Stats'!D:AT,42,FALSE) -> 66
C40: 10 | D40: =VLOOKUP(C40,'Data Staging Practice Stats'!B:D,3,FALSE) -> South Georgia Family Practice | E40: =VLOOKUP(D40,'Data Staging Practice Stats'!D:AT,43,FALSE) -> 144 | F40: =VLOOKUP(D40,'Data Staging Practice Stats'!D:AT,41,FALSE) -> 68 | G40: =VLOOKUP(D40,'Data Staging Practice Stats'!D:AT,42,FALSE) -> 76
C41: 11 | D41: =VLOOKUP(C41,'Data Staging Practice Stats'!B:D,3,FALSE) -> Central Georigia Medical Practice | E41: =VLOOKUP(D41,'Data Staging Practice Stats'!D:AT,43,FALSE) -> 142 | F41: =VLOOKUP(D41,'Data Staging Practice Stats'!D:AT,41,FALSE) -> 73 | G41: =VLOOKUP(D41,'Data Staging Practice Stats'!D:AT,42,FALSE) -> 69
...

Sheet Data Staging Provider Stats
AT3: 45658
E5: 45566 | F5: 45566 | G5: 45566 | H5: 45597 | I5: 45597 | J5: 45597 | K5: 45627 | L5: 45627 | M5: 45627 | N5: 45658 | O5: 45658 | P5: 45658 | Q5: 45689 | R5: 45689 | S5: 45689 | T5: 45717 | U5: 45717 | V5: 45717 | W5: 45748 | X5: 45748 | Y5: 45748 | Z5: 45778 | AA5: 45778 | AB5: 45778 | AC5: 45809 | AD5: 45809 | AE5: 45809 | AF5: 45839 | AG5: 45839 | AH5: 45839 | AI5: 45870 | AJ5: 45870 | AK5: 45870 | AL5: 45901 | AM5: 45901 | AN5: 45901 | AO5: 45931 | AP5: 45931 | AQ5: 45931 | AR5: YTD | AS5: YTD | AT5: YTD
E6: New Patients | F6: OA NewPt - Colonoscopy | G6: Total | H6: New Patients | I6: OA NewPt - Colonoscopy | J6: Total | K6: New Patients | L6: OA NewPt - Colonoscopy | M6: Total | N6: New Patients | O6: OA NewPt - Colonoscopy | P6: Total | Q6: New Patients | R6: OA NewPt - Colonoscopy | S6: Total | T6: New Patients | U6: OA NewPt - Colonoscopy | V6: Total | W6: New Patients | X6: OA NewPt - Colonoscopy | Y6: Total | Z6: New Patients | AA6: OA NewPt - Colonoscopy | AB6: Total | AC6: New Patients | AD6: OA NewPt - Colonoscopy | AE6: Total | AF6: New Patients | AG6: OA NewPt - Colonoscopy | AH6: Total | AI6: New Patients | AJ6: OA NewPt - Colonoscopy | AK6: Total | AL6: New Patients | AM6: OA NewPt - Colonoscopy | AN6: Total | AO6: New Patients | AP6: OA NewPt - Colonoscopy | AQ6: Total | AR6: New Patients | AS6: OA NewPt - Colonoscopy | AT6: Total
C7: Practice Name | D7: Total | E7: 129 | F7: 129 | G7: 258 | H7: 118 | I7: 117 | J7: 235 | K7: 102 | L7: 102 | M7: 204 | N7: 124 | O7: 104 | P7: 228 | Q7: 99 | R7: 128 | S7: 227 | T7: 110 | U7: 126 | V7: 236 | W7: 120 | X7: 109 | Y7: 229 | Z7: 121 | AA7: 118 | AB7: 239 | AC7: 107 | AD7: 109 | AE7: 216 | AF7: 112 | AG7: 115 | AH7: 227 | AI7: 114 | AJ7: 109 | AK7: 223 | AL7: 76 | AM7: 97 | AN7: 173 | AO7: 130 | AP7: 115 | AQ7: 245 | AR7: 1113 | AS7: 1130 | AT7: 2243
A8: 14 | B8: 1 | C8: Georgia Medical Clinic | D8: Maria Jacobson | E8: 6 | F8: 6 | G8: 12 | H8: 11 | I8: 8 | J8: 19 | K8: 14 | L8: 7 | M8: 21 | N8: 1 | O8: 8 | P8: 9 | Q8: 9 | R8: 11 | S8: 20 | T8: 5 | U8: 5 | V8: 10 | W8: 6 | X8: 12 | Y8: 18 | Z8: 9 | AA8: 7 | AB8: 16 | AC8: 8 | AD8: 5 | AE8: 13 | AF8: 3 | AG8: 7 | AH8: 10 | AI8: 6 | AJ8: 8 | AK8: 14 | AL8: 1 | AM8: 3 | AN8: 4 | AO8: 7 | AP8: 8 | AQ8: 15 | AR8: 55 | AS8: 74 | AT8: 129
A9: 13 | B9: 2 | C9: Family Medical Practice | D9: Martha Thompson | E9: 10 | F9: 9 | G9: 19 | H9: 8 | I9: 12 | J9: 20 | K9: 6 | L9: 8 | M9: 14 | N9: 10 | O9: 8 | P9: 18 | Q9: 5 | R9: 9 | S9: 14 | T9: 7 | U9: 5 | V9: 12 | W9: 8 | X9: 6 | Y9: 14 | Z9: 9 | AA9: 5 | AB9: 14 | AC9: 3 | AD9: 5 | AE9: 8 | AF9: 6 | AG9: 9 | AH9: 15 | AI9: 9 | AJ9: 8 | AK9: 17 | AL9: 6 | AM9: 2 | AN9: 8 | AO9: 9 | AP9: 8 | AQ9: 17 | AR9: 72 | AS9: 65 | AT9: 137
A10: 1 | B10: 3 | C10: North Georiga Medical Clinic | D10: Marcel Hilton | E10: 20 | F10: 13 | G10: 33 | H10: 15 | I10: 18 | J10: 33 | K10: 12 | L10: 11 | M10: 23 | N10: 18 | O10: 14 | P10: 32 | Q10: 17 | R10: 17 | S10: 34 | T10: 14 | U10: 17 | V10: 31 | W10: 19 | X10: 15 | Y10: 34 | Z10: 8 | AA10: 13 | AB10: 21 | AC10: 19 | AD10: 15 | AE10: 34 | AF10: 14 | AG10: 19 | AH10: 33 | AI10: 16 | AJ10: 15 | AK10: 31 | AL10: 9 | AM10: 18 | AN10: 27 | AO10: 24 | AP10: 16 | AQ10: 40 | AR10: 158 | AS10: 159 | AT10: 317
A11: 8 | B11: 4 | C11: East Georgia Medical Practice | D11: Larry Brown | E11: 3 | F11: 10 | G11: 13 | H11: 10 | I11: 4 | J11: 14 | K11: 7 | L11: 10 | M11: 17 | N11: 4 | O11: 12 | P11: 16 | Q11: 10 | R11: 11 | S11: 21 | T11: 4 | U11: 5 | V11: 9 | W11: 6 | X11: 9 | Y11: 15 | Z11: 9 | AA11: 10 | AB11: 19 | AC11: 6 | AD11: 8 | AE11: 14 | AF11: 8 | AG11: 5 | AH11: 13 | AI11: 4 | AJ11: 8 | AK11: 12 | AL11: 6 | AM11: 8 | AN11: 14 | AO11: 11 | AP11: 4 | AQ11: 15 | AR11: 68 | AS11: 80 | AT11: 148
A12: 9 | B12: 5 | C12: North Georgia Wellness Center | D12: Jenny Cameron | E12: 4 | F12: 9 | G12: 13 | H12: 4 | I12: 5 | J12: 9 | K12: 8 | L12: 8 | M12: 16 | N12: 15 | O12: 3 | P12: 18 | Q12: 6 | R12: 9 | S12: 15 | T12: 5 | U12: 9 | V12: 14 | W12: 7 | X12: 6 | Y12: 13 | Z12: 7 | AA12: 5 | AB12: 12 | AC12: 9 | AD12: 14 | AE12: 23 | AF12: 7 | AG12: 8 | AH12: 15 | AI12: 9 | AJ12: 5 | AK12: 14 | AL12: 8 | AM12: 2 | AN12: 10 | AO12: 6 | AP12: 5 | AQ12: 11 | AR12: 79 | AS12: 66 | AT12: 145
A13: 6 | B13: 6 | C13: Community Health Center | D13: Kelly Smith | E13: 8 | F13: 6 | G13: 14 | H13: 7 | I13: 6 | J13: 13 | K13: 8 | L13: 6 | M13: 14 | N13: 8 | O13: 4 | P13: 12 | Q13: 7 | R13: 8 | S13: 15 | T13: 6 | U13: 5 | V13: 11 | W13: 9 | X13: 5 | Y13: 14 | Z13: 13 | AA13: 9 | AB13: 22 | AC13: 6 | AD13: 9 | AE13: 15 | AF13: 7 | AG13: 14 | AH13: 21 | AI13: 6 | AJ13: 6 | AK13: 12 | AL13: 10 | AM13: 6 | AN13: 16 | AO13: 7 | AP13: 6 | AQ13: 13 | AR13: 79 | AS13: 72 | AT13: 151
A14: 12 | B14: 7 | C14: Georgia Medical Partners | D14: Donald Holmes | E14: 6 | F14: 10 | G14: 16 | H14: 7 | I14: 12 | J14: 19 | K14: 9 | L14: 8 | M14: 17 | N14: 10 | O14: 7 | P14: 17 | Q14: 5 | R14: 7 | S14: 12 | T14: 9 | U14: 4 | V14: 13 | W14: 3 | X14: 3 | Y14: 6 | Z14: 7 | AA14: 9 | AB14: 16 | AC14: 8 | AD14: 8 | AE14: 16 | AF14: 12 | AG14: 9 | AH14: 21 | AI14: 7 | AJ14: 4 | AK14: 11 | AL14: 1 | AM14: 7 | AN14: 8 | AO14: 10 | AP14: 7 | AQ14: 17 | AR14: 72 | AS14: 65 | AT14: 137
A15: 10 | B15: 8 | C15: South Georgia Family Practice | D15: Fredrick Johnson | E15: 7 | F15: 10 | G15: 17 | H15: 9 | I15: 11 | J15: 20 | K15: 5 | L15: 7 | M15: 12 | N15: 8 | O15: 8 | P15: 16 | Q15: 2 | R15: 5 | S15: 7 | T15: 9 | U15: 19 | V15: 28 | W15: 5 | X15: 3 | Y15: 8 | Z15: 8 | AA15: 9 | AB15: 17 | AC15: 5 | AD15: 4 | AE15: 9 | AF15: 14 | AG15: 6 | AH15: 20 | AI15: 9 | AJ15: 8 | AK15: 17 | AL15: 5 | AM15: 7 | AN15: 12 | AO15: 3 | AP15: 7 | AQ15: 10 | AR15: 68 | AS15: 76 | AT15: 144
A16: 4 | B16: 9 | C16: Georgia Urgent Care Center | D16: Jerry Smith | E16: 12 | F16: 11 | G16: 23 | H16: 7 | I16: 11 | J16: 18 | K16: 7 | L16: 5 | M16: 12 | N16: 8 | O16: 9 | P16: 17 | Q16: 5 | R16: 5 | S16: 10 | T16: 7 | U16: 10 | V16: 17 | W16: 11 | X16: 9 | Y16: 20 | Z16: 7 | AA16: 8 | AB16: 15 | AC16: 5 | AD16: 7 | AE16: 12 | AF16: 6 | AG16: 8 | AH16: 14 | AI16: 12 | AJ16: 6 | AK16: 18 | AL16: 4 | AM16: 8 | AN16: 12 | AO16: 12 | AP16: 7 | AQ16: 19 | AR16: 77 | AS16: 77 | AT16: 154
A17: 7 | B17: 10 | C17: Emergency Medical Clinic | D17: Jessie Williams | E17: 12 | F17: 10 | G17: 22 | H17: 8 | I17: 4 | J17: 12 | K17: 6 | L17: 6 | M17: 12 | N17: 9 | O17: 6 | P17: 15 | Q17: 6 | R17: 10 | S17: 16 | T17: 6 | U17: 9 | V17: 15 | W17: 13 | X17: 7 | Y17: 20 | Z17: 9 | AA17: 9 | AB17: 18 | AC17: 10 | AD17: 6 | AE17: 16 | AF17: 7 | AG17: 5 | AH17: 12 | AI17: 5 | AJ17: 8 | AK17: 13 | AL17: 3 | AM17: 4 | AN17: 7 | AO17: 8 | AP17: 10 | AQ17: 18 | AR17: 76 | AS17: 74 | AT17: 150
A18: 11 | B18: 11 | C18: Central Georigia Medical Practice | D18: John Doe | E18: 8 | F18: 9 | G18: 17 | H18: 2 | I18: 4 | J18: 6 | K18: 4 | L18: 8 | M18: 12 | N18: 9 | O18: 5 | P18: 14 | Q18: 6 | R18: 8 | S18: 14 | T18: 8 | U18: 11 | V18: 19 | W18: 10 | X18: 8 | Y18: 18 | Z18: 6 | AA18: 9 | AB18: 15 | AC18: 9 | AD18: 5 | AE18: 14 | AF18: 10 | AG18: 5 | AH18: 15 | AI18: 4 | AJ18: 7 | AK18: 11 | AL18: 4 | AM18: 5 | AN18: 9 | AO18: 7 | AP18: 6 | AQ18: 13 | AR18: 73 | AS18: 69 | AT18: 142
A19: 5 | B19: 12 | C19: Prime Care Medical Center | D19: Sabrina Byrd | E19: 10 | F19: 9 | G19: 19 | H19: 11 | I19: 8 | J19: 19 | K19: 5 | L19: 7 | M19: 12 | N19: 4 | O19: 6 | P19: 10 | Q19: 7 | R19: 8 | S19: 15 | T19: 6 | U19: 11 | V19: 17 | W19: 12 | X19: 9 | Y19: 21 | Z19: 8 | AA19: 8 | AB19: 16 | AC19: 7 | AD19: 5 | AE19: 12 | AF19: 4 | AG19: 9 | AH19: 13 | AI19: 8 | AJ19: 14 | AK19: 22 | AL19: 4 | AM19: 9 | AN19: 13 | AO19: 4 | AP19: 9 | AQ19: 13 | AR19: 64 | AS19: 88 | AT19: 152
... A22: 15 | B22: 15 | C22: Georgia Healthcare Center | D22: Frank Fredson | E22: 3 | F22: 4 | G22: 7 | H22: 1 | I22: 0 | J22: 1 | K22: 0 | L22: 0 | M22: 0 | N22: 0 | O22: 1 | P22: 1 | Q22: 0 | R22: 0 | S22: 0 | T22: 2 | U22: 0 | V22: 2 | W22: 0 | X22: 2 | Y22: 2 | Z22: 1 | AA22: 0 | AB22: 1 | AC22: 0 | AD22: 1 | AE22: 1 | AF22: 2 | AG22: 0 | AH22: 2 | AI22: 1 | AJ22: 1 | AK22: 2 | AL22: 2 | AM22: 1 | AN22: 3 | AO22: 0 | AP22: 1 | AQ22: 1 | AR22: 8 | AS22: 7 | AT22: 15
A23: 996 | B23: 16 | C23: Practice Not Known | E23: 0 | F23: 0 | G23: 0 | H23: 0 | I23: 0 | J23: 0 | K23: 0 | L23: 0 | M23: 0 | N23: 0 | O23: 0 | P23: 0 | Q23: 0 | R23: 0 | S23: 0 | T23: 0 | U23: 0 | V23: 0 | W23: 0 | X23: 0 | Y23: 0 | Z23: 0 | AA23: 0 | AB23: 0 | AC23: 0 | AD23: 0 | AE23: 0 | AF23: 0 | AG23: 0 | AH23: 0 | AI23: 0 | AJ23: 0 | AK23: 0 | AL23: 0 | AM23: 0 | AN23: 0 | AO23: 0 | AP23: 0 | AQ23: 0 | AR23: 0 | AS23: 0 | AT23: 0
A24: 995 | B24: 17 | C24: Practice Not Known | E24: 0 | F24: 0 | G24: 0 | H24: 0 | I24: 0 | J24: 0 | K24: 0 | L24: 0 | M24: 0 | N24: 0 | O24: 0 | P24: 0 | Q24: 0 | R24: 0 | S24: 0 | T24: 0 | U24: 0 | V24: 0 | W24: 0 | X24: 0 | Y24: 0 | Z24: 0 | AA24: 0 | AB24: 0 | AC24: 0 | AD24: 0 | AE24: 0 | AF24: 0 | AG24: 0 | AH24: 0 | AI24: 0 | AJ24: 0 | AK24: 0 | AL24: 0 | AM24: 0 | AN24: 0 | AO24: 0 | AP24: 0 | AQ24: 0 | AR24: 0 | AS24: 0 | AT24: 0
A25: 994 | B25: 18 | C25: Practice Not Known | E25: 0 | F25: 0 | G25: 0 | H25: 0 | I25: 0 | J25: 0 | K25: 0 | L25: 0 | M25: 0 | N25: 0 | O25: 0 | P25: 0 | Q25: 0 | R25: 0 | S25: 0 | T25: 0 | U25: 0 | V25: 0 | W25: 0 | X25: 0 | Y25: 0 | Z25: 0 | AA25: 0 | AB25: 0 | AC25: 0 | AD25: 0 | AE25: 0 | AF25: 0 | AG25: 0 | AH25: 0 | AI25: 0 | AJ25: 0 | AK25: 0 | AL25: 0 | AM25: 0 | AN25: 0 | AO25: 0 | AP25: 0 | AQ25: 0 | AR25: 0 | AS25: 0 | AT25: 0
A26: 993 | B26: 19 | C26: Practice Not Known | E26: 0 | F26: 0 | G26: 0 | H26: 0 | I26: 0 | J26: 0 | K26: 0 | L26: 0 | M26: 0 | N26: 0 | O26: 0 | P26: 0 | Q26: 0 | R26: 0 | S26: 0 | T26: 0 | U26: 0 | V26: 0 | W26: 0 | X26: 0 | Y26: 0 | Z26: 0 | AA26: 0 | AB26: 0 | AC26: 0 | AD26: 0 | AE26: 0 | AF26: 0 | AG26: 0 | AH26: 0 | AI26: 0 | AJ26: 0 | AK26: 0 | AL26: 0 | AM26: 0 | AN26: 0 | AO26: 0 | AP26: 0 | AQ26: 0 | AR26: 0 | AS26: 0 | AT26: 0
A27: 992 | B27: 20 | C27: Practice Not Known | E27: 0 | F27: 0 | G27: 0 | H27: 0 | I27: 0 | J27: 0 | K27: 0 | L27: 0 | M27: 0 | N27: 0 | O27: 0 | P27: 0 | Q27: 0 | R27: 0 | S27: 0 | T27: 0 | U27: 0 | V27: 0 | W27: 0 | X27: 0 | Y27: 0 | Z27: 0 | AA27: 0 | AB27: 0 | AC27: 0 | AD27: 0 | AE27: 0 | AF27: 0 | AG27: 0 | AH27: 0 | AI27: 0 | AJ27: 0 | AK27: 0 | AL27: 0 | AM27: 0 | AN27: 0 | AO27: 0 | AP27: 0 | AQ27: 0 | AR27: 0 | AS27: 0 | AT27: 0
A28: 991 | B28: 21 | C28: Practice Not Known | E28: 0 | F28: 0 | G28: 0 | H28: 0 | I28: 0 | J28: 0 | K28: 0 | L28: 0 | M28: 0 | N28: 0 | O28: 0 | P28: 0 | Q28: 0 | R28: 0 | S28: 0 | T28: 0 | U28: 0 | V28: 0 | W28: 0 | X28: 0 | Y28: 0 | Z28: 0 | AA28: 0 | AB28: 0 | AC28: 0 | AD28: 0 | AE28: 0 | AF28: 0 | AG28: 0 | AH28: 0 | AI28: 0 | AJ28: 0 | AK28: 0 | AL28: 0 | AM28: 0 | AN28: 0 | AO28: 0 | AP28: 0 | AQ28: 0 | AR28: 0 | AS28: 0 | AT28: 0
A29: 990 | B29: 22 | C29: Practice Not Known | E29: 0 | F29: 0 | G29: 0 | H29: 0 | I29: 0 | J29: 0 | K29: 0 | L29: 0 | M29: 0 | N29: 0 | O29: 0 | P29: 0 | Q29: 0 | R29: 0 | S29: 0 | T29: 0 | U29: 0 | V29: 0 | W29: 0 | X29: 0 | Y29: 0 | Z29: 0 | AA29: 0 | AB29: 0 | AC29: 0 | AD29: 0 | AE29: 0 | AF29: 0 | AG29: 0 | AH29: 0 | AI29: 0 | AJ29: 0 | AK29: 0 | AL29: 0 | AM29: 0 | AN29: 0 | AO29: 0 | AP29: 0 | AQ29: 0 | AR29: 0 | AS29: 0 | AT29: 0
A30: 989 | B30: 23 | C30: Practice Not Known | E30: 0 | F30: 0 | G30: 0 | H30: 0 | I30: 0 | J30: 0 | K30: 0 | L30: 0 | M30: 0 | N30: 0 | O30: 0 | P30: 0 | Q30: 0 | R30: 0 | S30: 0 | T30: 0 | U30: 0 | V30: 0 | W30: 0 | X30: 0 | Y30: 0 | Z30: 0 | AA30: 0 | AB30: 0 | AC30: 0 | AD30: 0 | AE30: 0 | AF30: 0 | AG30: 0 | AH30: 0 | AI30: 0 | AJ30: 0 | AK30: 0 | AL30: 0 | AM30: 0 | AN30: 0 | AO30: 0 | AP30: 0 | AQ30: 0 | AR30: 0 | AS30: 0 | AT30: 0
A31: 988 | B31: 24 | C31: Practice Not Known | E31: 0 | F31: 0 | G31: 0 | H31: 0 | I31: 0 | J31: 0 | K31: 0 | L31: 0 | M31: 0 | N31: 0 | O31: 0 | P31: 0 | Q31: 0 | R31: 0 | S31: 0 | T31: 0 | U31: 0 | V31: 0 | W31: 0 | X31: 0 | Y31: 0 | Z31: 0 | AA31: 0 | AB31: 0 | AC31: 0 | AD31: 0 | AE31: 0 | AF31: 0 | AG31: 0 | AH31: 0 | AI31: 0 | AJ31: 0 | AK31: 0 | AL31: 0 | AM31: 0 | AN31: 0 | AO31: 0 | AP31: 0 | AQ31: 0 | AR31: 0 | AS31: 0 | AT31: 0
A32: 987 | B32: 25 | C32: Practice Not Known | E32: 0 | F32: 0 | G32: 0 | H32: 0 | I32: 0 | J32: 0 | K32: 0 | L32: 0 | M32: 0 | N32: 0 | O32: 0 | P32: 0 | Q32: 0 | R32: 0 | S32: 0 | T32: 0 | U32: 0 | V32: 0 | W32: 0 | X32: 0 | Y32: 0 | Z32: 0 | AA32: 0 | AB32: 0 | AC32: 0 | AD32: 0 | AE32: 0 | AF32: 0 | AG32: 0 | AH32: 0 | AI32: 0 | AJ32: 0 | AK32: 0 | AL32: 0 | AM32: 0 | AN32: 0 | AO32: 0 | AP32: 0 | AQ32: 0 | AR32: 0 | AS32: 0 | AT32: 0
A33: 986 | B33: 26 | C33: Practice Not Known | E33: 0 | F33: 0 | G33: 0 | H33: 0 | I33: 0 | J33: 0 | K33: 0 | L33: 0 | M33: 0 | N33: 0 | O33: 0 | P33: 0 | Q33: 0 | R33: 0 | S33: 0 | T33: 0 | U33: 0 | V33: 0 | W33: 0 | X33: 0 | Y33: 0 | Z33: 0 | AA33: 0 | AB33: 0 | AC33: 0 | AD33: 0 | AE33: 0 | AF33: 0 | AG33: 0 | AH33: 0 | AI33: 0 | AJ33: 0 | AK33: 0 | AL33: 0 | AM33: 0 | AN33: 0 | AO33: 0 | AP33: 0 | AQ33: 0 | AR33: 0 | AS33: 0 | AT33: 0
A34: 985 | B34: 27 | C34: Practice Not Known | E34: 0 | F34: 0 | G34: 0 | H34: 0 | I34: 0 | J34: 0 | K34: 0 | L34: 0 | M34: 0 | N34: 0 | O34: 0 | P34: 0 | Q34: 0 | R34: 0 | S34: 0 | T34: 0 | U34: 0 | V34: 0 | W34: 0 | X34: 0 | Y34: 0 | Z34: 0 | AA34: 0 | AB34: 0 | AC34: 0 | AD34: 0 | AE34: 0 | AF34: 0 | AG34: 0 | AH34: 0 | AI34: 0 | AJ34: 0 | AK34: 0 | AL34: 0 | AM34: 0 | AN34: 0 | AO34: 0 | AP34: 0 | AQ34: 0 | AR34: 0 | AS34: 0 | AT34: 0
... A1003: 16 | B1003: 996 | C1003: Practice Not Known | E1003: 0 | F1003: 0 | G1003: 0 | H1003: 0 | I1003: 0 | J1003: 0 | K1003: 0 | L1003: 0 | M1003: 0 | N1003: 0 | O1003: 0 | P1003: 0 | Q1003: 0 | R1003: 0 | S1003: 0 | T1003: 0 | U1003: 0 | V1003: 0 | W1003: 0 | X1003: 0 | Y1003: 0 | Z1003: 0 | AA1003: 0 | AB1003: 0 | AC1003: 0 | AD1003: 0 | AE1003: 0 | AF1003: 0 | AG1003: 0 | AH1003: 0 | AI1003: 0 | AJ1003: 0 | AK1003: 0 | AL1003: 0 | AM1003: 0 | AN1003: 0 | AO1003: 0 | AP1003: 0 | AQ1003: 0 | AR1003: 0 | AS1003: 0 | AT1003: 0

Sheet Data Staging Lag
R3: 45292
E5: 45566 | F5: 45597 | G5: 45627 | H5: 45658 | I5: 45689 | J5: 45717 | K5: 45748 | L5: 45778 | M5: 45809 | N5: 45839 | O5: 45870 | P5: 45901 | Q5: 45931 | R5: YTD
C6: Count | D6: Total | E6: 414 | F6: 353 | G6: 299 | H6: 331 | I6: 362 | J6: 366 | K6: 351 | L6: 384 | M6: 325 | N6: 332 | O6: 367 | P6: 276 | Q6: 366 | R6: 4526
D7: New Patients | E7: 129 | F7: 118 | G7: 102 | H7: 124 | I7: 99 | J7: 110 | K7: 120 | L7: 121 | M7: 107 | N7: 112 | O7: 114 | P7: 76 | Q7: 130 | R7: 1462
D8: OA NewPt - Colonoscopy | E8: 129 | F8: 117 | G8: 102 | H8: 104 | I8: 128 | J8: 126 | K8: 109 | L8: 118 | M8: 109 | N8: 115 | O8: 109 | P8: 97 | Q8: 115 | R8: 1478
D9: Re-Establishing | E9: 156 | F9: 118 | G9: 95 | H9: 103 | I9: 135 | J9: 130 | K9: 122 | L9: 145 | M9: 109 | N9: 105 | O9: 144 | P9: 103 | Q9: 121 | R9: 1586
D10: Telehealth NP | E10: 0 | F10: 0 | G10: 0 | H10: 0 | I10: 0 | J10: 0 | K10: 0 | L10: 0 | M10: 0 | N10: 0 | O10: 0 | P10: 0 | Q10: 0 | R10: 0
C12: Lag | D12: New Patients | E12: 2007 | F12: 2067 | G12: 1660 | H12: 2260 | I12: 1577 | J12: 1743 | K12: 2169 | L12: 2307 | M12: 2212 | N12: 1834 | O12: 2401 | P12: 1827 | Q12: 2182 | R12: 26246
D13: OA NewPt - Colonoscopy | E13: 2269 | F13: 2004 | G13: 1641 | H13: 1699 | I13: 2016 | J13: 2241 | K13: 1731 | L13: 2328 | M13: 1957 | N13: 1957 | O13: 1822 | P13: 2182 | Q13: 2141 | R13: 25988
D14: Re-Establishing | E14: 2702 | F14: 2093 | G14: 1772 | H14: 1816 | I14: 1841 | J14: 2037 | K14: 1769 | L14: 2585 | M14: 2175 | N14: 1693 | O14: 3398 | P14: 2537 | Q14: 2280 | R14: 28698
D15: Telehealth NP | E15: 0 | F15: 0 | G15: 0 | H15: 0 | I15: 0 | J15: 0 | K15: 0 | L15: 0 | M15: 0 | N15: 0 | O15: 0 | P15: 0 | Q15: 0 | R15: 0
C17: Avg Lag | D17: New Patients | E17: 15.55814 | F17: 17.516949 | G17: 16.27451 | H17: 18.225806 | I17: 15.929293 | J17: 15.845455 | K17: 18.075 | L17: 19.066116 | M17: 20.672897 | N17: 16.375 | O17: 21.061404 | P17: 24.039474 | Q17: 16.784615 | R17: 17.95212
D18: OA NewPt - Colonoscopy | E18: 17.589147 | F18: 17.128205 | G18: 16.088235 | H18: 16.336538 | I18: 15.75 | J18: 17.785714 | K18: 15.880734 | L18: 19.728814 | M18: 17.954128 | N18: 17.017391 | O18: 16.715596 | P18: 22.494845 | Q18: 18.617391 | R18: 17.583221
D19: Re-Establishing | E19: 17.320513 | F19: 17.737288 | G19: 18.652632 | H19: 17.631068 | I19: 13.637037 | J19: 15.669231 | K19: 14.5 | L19: 17.827586 | M19: 19.954128 | N19: 16.12381 | O19: 23.597222 | P19: 24.631068 | Q19: 18.842975 | R19: 18.094578
D20: Telehealth NP | E20: 0 | F20: 0 | G20: 0 | H20: 0 | I20: 0 | J20: 0 | K20: 0 | L20: 0 | M20: 0 | N20: 0 | O20: 0 | P20: 0 | Q20: 0 | R20: 0
C22: >14 days | D22: New Patients | E22: 45 | F22: 48 | G22: 42 | H22: 47 | I22: 35 | J22: 42 | K22: 46 | L22: 48 | M22: 53 | N22: 48 | O22: 57 | P22: 39 | Q22: 49 | R22: 599
D23: OA NewPt - Colonoscopy | E23: 45 | F23: 57 | G23: 41 | H23: 37 | I23: 48 | J23: 50 | K23: 37 | L23: 57 | M23: 42 | N23: 51 | O23: 48 | P23: 45 | Q23: 48 | R23: 606

Sheet Data Staging Practice Stats
E5: 45566 | F5: 45566 | G5: 45566 | H5: 45597 | I5: 45597 | J5: 45597 | K5: 45627 | L5: 45627 | M5: 45627 | N5: 45658 | O5: 45658 | P5: 45658 | Q5: 45689 | R5: 45689 | S5: 45689 | T5: 45717 | U5: 45717 | V5: 45717 | W5: 45748 | X5: 45748 | Y5: 45748 | Z5: 45778 | AA5: 45778 | AB5: 45778 | AC5: 45809 | AD5: 45809 | AE5: 45809 | AF5: 45839 | AG5: 45839 | AH5: 45839 | AI5: 45870 | AJ5: 45870 | AK5: 45870 | AL5: 45901 | AM5: 45901 | AN5: 45901 | AO5: 45931 | AP5: 45931 | AQ5: 45931 | AR5: YTD | AS5: YTD | AT5: YTD
D6: Practice | E6: New Patients | F6: OA NewPt - Colonoscopy | G6: Total | H6: New Patients | I6: OA NewPt - Colonoscopy | J6: Total | K6: New Patients | L6: OA NewPt - Colonoscopy | M6: Total | N6: New Patients | O6: OA NewPt - Colonoscopy | P6: Total | Q6: New Patients | R6: OA NewPt - Colonoscopy | S6: Total | T6: New Patients | U6: OA NewPt - Colonoscopy | V6: Total | W6: New Patients | X6: OA NewPt - Colonoscopy | Y6: Total | Z6: New Patients | AA6: OA NewPt - Colonoscopy | AB6: Total | AC6: New Patients | AD6: OA NewPt - Colonoscopy | AE6: Total | AF6: New Patients | AG6: OA NewPt - Colonoscopy | AH6: Total | AI6: New Patients | AJ6: OA NewPt - Colonoscopy | AK6: Total | AL6: New Patients | AM6: OA NewPt - Colonoscopy | AN6: Total | AO6: New Patients | AP6: OA NewPt - Colonoscopy | AQ6: Total | AR6: New Patients | AS6: OA NewPt - Colonoscopy | AT6: Total
